<?xml version="1.0"?>
<robot name="my_robot" xmlns:xacro="http://www.ros.org/wiki/xacro">

  <material name="grey">
    <color rgba="0.79216 0.81961 0.93333 1" />
  </material>

  <link name="base_link">
    <inertial>
      <origin xyz="-0.041771 -1.1102E-16 0.033857" rpy="0 0 0" />
      <mass value="1.407" />
      <inertia ixx="0.0024719" ixy="-1.3675E-18" ixz="0.00018646"
               iyy="0.00681"   iyz="1.095E-19"
               izz="0.0070135" />
    </inertial>
    <visual>
      <origin xyz="0 0 0" rpy="0 0 0" />
      <geometry>
        <mesh filename="package://my_robot_description/meshes/visual/base_link.STL" />
      </geometry>
      <material name="grey" />
    </visual>
    <collision>
      <origin xyz="0 0 0" rpy="0 0 0" />
      <geometry>
        <mesh filename="package://my_robot_description/meshes/collision/base_link.STL" />
      </geometry>
    </collision>
  </link>

  <link name="1st_Link">
    <inertial>
      <origin xyz="0.0543 -0.020673 0.046417" rpy="0 0 0" />
      <mass value="1.1495" />
      <inertia ixx="0.0032387" ixy="0.00017789" ixz="-0.00039788"
               iyy="0.0020161" iyz="0.00039611"
               izz="0.0027855" />
    </inertial>
    <visual>
      <origin xyz="0 0 0" rpy="0 0 0" />
      <geometry>
        <mesh filename="package://my_robot_description/meshes/visual/1st_Link.STL" />
      </geometry>
      <material name="grey" />
    </visual>
    <collision>
      <origin xyz="0 0 0" rpy="0 0 0" />
      <geometry>
        <mesh filename="package://my_robot_description/meshes/collision/1st_Link.STL" />
      </geometry>
    </collision>
  </link>

  <joint name="Joint_0" type="revolute">
    <origin xyz="0 0 0.0994" rpy="0 0 0" />
    <parent link="base_link" />
    <child link="1st_Link" />
    <axis xyz="0 0 -1" />
    <limit lower="-2.9671" upper="2.9671" effort="4" velocity="3.1" />
  </joint>

  <link name="2nd_Link">
    <inertial>
      <origin xyz="-1.5543E-15 -0.14784 -0.014918" rpy="0 0 0" />
      <mass value="0.8363" />
      <inertia ixx="0.008149"   ixy="9.6713E-18" ixz="-1.613E-18"
               iyy="0.00093169" iyz="0.00089805"
               izz="0.0076645" />
    </inertial>
    <visual>
      <origin xyz="0 0 0" rpy="0 0 0" />
      <geometry>
        <mesh filename="package://my_robot_description/meshes/visual/2nd_Link.STL" />
      </geometry>
      <material name="grey" />
    </visual>
    <collision>
      <origin xyz="0 0 0" rpy="0 0 0" />
      <geometry>
        <mesh filename="package://my_robot_description/meshes/collision/2nd_Link.STL" />
      </geometry>
    </collision>
  </link>

  <joint name="Joint_1" type="revolute">
    <origin xyz="0.064201 0.064413 0.069869" rpy="-1.5708 0 0" />
    <parent link="1st_Link" />
    <child link="2nd_Link" />
    <axis xyz="0 0 -1" />
    <limit lower="-0.733" upper="1.5708" effort="57" velocity="0.63" />
  </joint>

  <link name="3rd_Link">
    <inertial>
      <origin xyz="0.0020169 0.017836 -0.07504" rpy="0 0 0" />
      <mass value="0.27635" />
      <inertia ixx="0.00030182" ixy="3.1988E-05" ixz="-5.1391E-06"
               iyy="0.00023538" iyz="6.3261E-05"
               izz="0.00031122" />
    </inertial>
    <visual>
      <origin xyz="0 0 0" rpy="0 0 0" />
      <geometry>
        <mesh filename="package://my_robot_description/meshes/visual/3rd_Link.STL" />
      </geometry>
      <material name="grey" />
    </visual>
    <collision>
      <origin xyz="0 0 0" rpy="0 0 0" />
      <geometry>
        <mesh filename="package://my_robot_description/meshes/collision/3rd_Link.STL" />
      </geometry>
    </collision>
  </link>

  <joint name="Joint_2" type="revolute">
    <origin xyz="0 -0.305 0.016225" rpy="0 0 0" />
    <parent link="2nd_Link" />
    <child link="3rd_Link" />
    <axis xyz="0 0 1" />
    <limit lower="-1.5533" upper="0.9076" effort="20" velocity="0.63" />
  </joint>

  <link name="4th_Link">
    <inertial>
      <origin xyz="1.2523E-13 0.0044165 0.16589" rpy="0 0 0" />
      <mass value="0.58728" />
      <inertia ixx="0.0038961" ixy="6.9388E-13" ixz="-3.8354E-15"
               iyy="0.0037675" iyz="-5.2921E-05"
               izz="0.00034965" />
    </inertial>
    <visual>
      <origin xyz="0 0 0" rpy="0 0 0" />
      <geometry>
        <mesh filename="package://my_robot_description/meshes/visual/4th_Link.STL" />
      </geometry>
      <material name="grey" />
    </visual>
    <collision>
      <origin xyz="0 0 0" rpy="0 0 0" />
      <geometry>
        <mesh filename="package://my_robot_description/meshes/collision/4th_Link.STL" />
      </geometry>
    </collision>
  </link>

  <joint name="Joint_3" type="revolute">
    <origin xyz="-0.078271 0 -0.090625" rpy="-1.5708 0 -1.5708" />
    <parent link="3rd_Link" />
    <child link="4th_Link" />
    <axis xyz="0 0 -1" />
    <limit lower="-2.8798" upper="2.8798" effort="1.6" velocity="2" />
  </joint>

  <link name="5th_Link">
    <inertial>
      <origin xyz="4.8184E-14 -0.01065 -0.040384" rpy="0 0 0" />
      <mass value="0.13801" />
      <inertia ixx="0.00010569" ixy="-5.0825E-17" ixz="1.6311E-16"
               iyy="7.3011E-05" iyz="-7.9323E-06"
               izz="6.2637E-05" />
    </inertial>
    <visual>
      <origin xyz="0 0 0" rpy="0 0 0" />
      <geometry>
        <mesh filename="package://my_robot_description/meshes/visual/5th_Link.STL" />
      </geometry>
      <material name="grey" />
    </visual>
    <collision>
      <origin xyz="0 0 0" rpy="0 0 0" />
      <geometry>
        <mesh filename="package://my_robot_description/meshes/collision/5th_Link.STL" />
      </geometry>
    </collision>
  </link>

  <joint name="Joint_4" type="revolute">
    <origin xyz="0 -0.044813 0.29996" rpy="1.5708 0 0" />
    <parent link="4th_Link" />
    <child link="5th_Link" />
    <axis xyz="0 0 -1" />
    <limit lower="-1.8326" upper="1.8326" effort="81" velocity="0.16" />
  </joint>

  <link name="6th_Link">
    <inertial>
      <origin xyz="-2.2204E-16 0 -0.0070452" rpy="0 0 0" />
      <mass value="0.015303" />
      <inertia ixx="1.9052E-06" ixy="-1.4035E-19" ixz="-1.8528E-20"
               iyy="1.4167E-06" iyz="9.3992E-21"
               izz="2.619E-06" />
    </inertial>
    <visual>
      <origin xyz="0 0 0" rpy="0 0 0" />
      <geometry>
        <mesh filename="package://my_robot_description/meshes/visual/6th_Link.STL" />
      </geometry>
      <material name="grey" />
    </visual>
    <collision>
      <origin xyz="0 0 0" rpy="0 0 0" />
      <geometry>
        <mesh filename="package://my_robot_description/meshes/collision/6th_Link.STL" />
      </geometry>
    </collision>
  </link>

  <joint name="Joint_5" type="revolute">
    <origin xyz="0 0.03625 -0.045781" rpy="1.5708 0 3.1416" />
    <parent link="5th_Link" />
    <child link="6th_Link" />
    <axis xyz="0 0 1" />
    <limit lower="-2.7053" upper="2.7053" effort="2.4" velocity="1.65" />
  </joint>
  
</robot>